<?xml version="1.0" ?>
<!-- =================================================================================== -->
<!-- |    This document was autogenerated by xacro from urdf/spider.xacro              | -->
<!-- |    EDITING THIS FILE BY HAND IS NOT RECOMMENDED                                 | -->
<!-- =================================================================================== -->
<robot xmlns:xacro="http://www.ros.org/wiki/xacro" name="spider">
  <material name="silver">
    <color rgba="0.700 0.700 0.700 1.000"/>
  </material>
  <transmission name="Revolute 1_tran">
    <type>transmission_interface/SimpleTransmission</type>
    <joint name="Revolute 1">
      <hardwareInterface>hardware_interface/EffortJointInterface</hardwareInterface>
    </joint>
    <actuator name="Revolute 1_actr">
      <hardwareInterface>hardware_interface/EffortJointInterface</hardwareInterface>
      <mechanicalReduction>1</mechanicalReduction>
    </actuator>
  </transmission>
  <transmission name="Revolute 2_tran">
    <type>transmission_interface/SimpleTransmission</type>
    <joint name="Revolute 2">
      <hardwareInterface>hardware_interface/EffortJointInterface</hardwareInterface>
    </joint>
    <actuator name="Revolute 2_actr">
      <hardwareInterface>hardware_interface/EffortJointInterface</hardwareInterface>
      <mechanicalReduction>1</mechanicalReduction>
    </actuator>
  </transmission>
  <transmission name="Revolute 3_tran">
    <type>transmission_interface/SimpleTransmission</type>
    <joint name="Revolute 3">
      <hardwareInterface>hardware_interface/EffortJointInterface</hardwareInterface>
    </joint>
    <actuator name="Revolute 3_actr">
      <hardwareInterface>hardware_interface/EffortJointInterface</hardwareInterface>
      <mechanicalReduction>1</mechanicalReduction>
    </actuator>
  </transmission>
  <transmission name="Revolute 4_tran">
    <type>transmission_interface/SimpleTransmission</type>
    <joint name="Revolute 4">
      <hardwareInterface>hardware_interface/EffortJointInterface</hardwareInterface>
    </joint>
    <actuator name="Revolute 4_actr">
      <hardwareInterface>hardware_interface/EffortJointInterface</hardwareInterface>
      <mechanicalReduction>1</mechanicalReduction>
    </actuator>
  </transmission>
  <transmission name="Revolute 5_tran">
    <type>transmission_interface/SimpleTransmission</type>
    <joint name="Revolute 5">
      <hardwareInterface>hardware_interface/EffortJointInterface</hardwareInterface>
    </joint>
    <actuator name="Revolute 5_actr">
      <hardwareInterface>hardware_interface/EffortJointInterface</hardwareInterface>
      <mechanicalReduction>1</mechanicalReduction>
    </actuator>
  </transmission>
  <transmission name="Revolute 6_tran">
    <type>transmission_interface/SimpleTransmission</type>
    <joint name="Revolute 6">
      <hardwareInterface>hardware_interface/EffortJointInterface</hardwareInterface>
    </joint>
    <actuator name="Revolute 6_actr">
      <hardwareInterface>hardware_interface/EffortJointInterface</hardwareInterface>
      <mechanicalReduction>1</mechanicalReduction>
    </actuator>
  </transmission>
  <transmission name="Revolute 7_tran">
    <type>transmission_interface/SimpleTransmission</type>
    <joint name="Revolute 7">
      <hardwareInterface>hardware_interface/EffortJointInterface</hardwareInterface>
    </joint>
    <actuator name="Revolute 7_actr">
      <hardwareInterface>hardware_interface/EffortJointInterface</hardwareInterface>
      <mechanicalReduction>1</mechanicalReduction>
    </actuator>
  </transmission>
  <transmission name="Revolute 8_tran">
    <type>transmission_interface/SimpleTransmission</type>
    <joint name="Revolute 8">
      <hardwareInterface>hardware_interface/EffortJointInterface</hardwareInterface>
    </joint>
    <actuator name="Revolute 8_actr">
      <hardwareInterface>hardware_interface/EffortJointInterface</hardwareInterface>
      <mechanicalReduction>1</mechanicalReduction>
    </actuator>
  </transmission>
  <transmission name="Revolute 9_tran">
    <type>transmission_interface/SimpleTransmission</type>
    <joint name="Revolute 9">
      <hardwareInterface>hardware_interface/EffortJointInterface</hardwareInterface>
    </joint>
    <actuator name="Revolute 9_actr">
      <hardwareInterface>hardware_interface/EffortJointInterface</hardwareInterface>
      <mechanicalReduction>1</mechanicalReduction>
    </actuator>
  </transmission>
  <transmission name="Revolute 10_tran">
    <type>transmission_interface/SimpleTransmission</type>
    <joint name="Revolute 10">
      <hardwareInterface>hardware_interface/EffortJointInterface</hardwareInterface>
    </joint>
    <actuator name="Revolute 10_actr">
      <hardwareInterface>hardware_interface/EffortJointInterface</hardwareInterface>
      <mechanicalReduction>1</mechanicalReduction>
    </actuator>
  </transmission>
  <transmission name="Revolute 11_tran">
    <type>transmission_interface/SimpleTransmission</type>
    <joint name="Revolute 11">
      <hardwareInterface>hardware_interface/EffortJointInterface</hardwareInterface>
    </joint>
    <actuator name="Revolute 11_actr">
      <hardwareInterface>hardware_interface/EffortJointInterface</hardwareInterface>
      <mechanicalReduction>1</mechanicalReduction>
    </actuator>
  </transmission>
  <transmission name="Revolute 12_tran">
    <type>transmission_interface/SimpleTransmission</type>
    <joint name="Revolute 12">
      <hardwareInterface>hardware_interface/EffortJointInterface</hardwareInterface>
    </joint>
    <actuator name="Revolute 12_actr">
      <hardwareInterface>hardware_interface/EffortJointInterface</hardwareInterface>
      <mechanicalReduction>1</mechanicalReduction>
    </actuator>
  </transmission>
  <transmission name="Revolute 13_tran">
    <type>transmission_interface/SimpleTransmission</type>
    <joint name="Revolute 13">
      <hardwareInterface>hardware_interface/EffortJointInterface</hardwareInterface>
    </joint>
    <actuator name="Revolute 13_actr">
      <hardwareInterface>hardware_interface/EffortJointInterface</hardwareInterface>
      <mechanicalReduction>1</mechanicalReduction>
    </actuator>
  </transmission>
  <transmission name="Revolute 14_tran">
    <type>transmission_interface/SimpleTransmission</type>
    <joint name="Revolute 14">
      <hardwareInterface>hardware_interface/EffortJointInterface</hardwareInterface>
    </joint>
    <actuator name="Revolute 14_actr">
      <hardwareInterface>hardware_interface/EffortJointInterface</hardwareInterface>
      <mechanicalReduction>1</mechanicalReduction>
    </actuator>
  </transmission>
  <transmission name="Revolute 15_tran">
    <type>transmission_interface/SimpleTransmission</type>
    <joint name="Revolute 15">
      <hardwareInterface>hardware_interface/EffortJointInterface</hardwareInterface>
    </joint>
    <actuator name="Revolute 15_actr">
      <hardwareInterface>hardware_interface/EffortJointInterface</hardwareInterface>
      <mechanicalReduction>1</mechanicalReduction>
    </actuator>
  </transmission>
  <transmission name="Revolute 16_tran">
    <type>transmission_interface/SimpleTransmission</type>
    <joint name="Revolute 16">
      <hardwareInterface>hardware_interface/EffortJointInterface</hardwareInterface>
    </joint>
    <actuator name="Revolute 16_actr">
      <hardwareInterface>hardware_interface/EffortJointInterface</hardwareInterface>
      <mechanicalReduction>1</mechanicalReduction>
    </actuator>
  </transmission>
  <gazebo>
    <plugin name="control" filename="libgazebo_ros_control.so"/>
  </gazebo>
  <gazebo reference="base_link">
    <material>Gazebo/Silver</material>
    <mu1>0.2</mu1>
    <mu2>0.2</mu2>
    <selfCollide>true</selfCollide>
    <gravity>true</gravity>
  </gazebo>
  <gazebo reference="Plink_board_1">
    <material>Gazebo/Silver</material>
    <mu1>0.2</mu1>
    <mu2>0.2</mu2>
    <selfCollide>true</selfCollide>
  </gazebo>
  <gazebo reference="Plink_board_2">
    <material>Gazebo/Silver</material>
    <mu1>0.2</mu1>
    <mu2>0.2</mu2>
    <selfCollide>true</selfCollide>
  </gazebo>
  <gazebo reference="Nlink_board_1">
    <material>Gazebo/Silver</material>
    <mu1>0.2</mu1>
    <mu2>0.2</mu2>
    <selfCollide>true</selfCollide>
  </gazebo>
  <gazebo reference="Nlink_board_2">
    <material>Gazebo/Silver</material>
    <mu1>0.2</mu1>
    <mu2>0.2</mu2>
    <selfCollide>true</selfCollide>
  </gazebo>
  <gazebo reference="Nlink_board_3">
    <material>Gazebo/Silver</material>
    <mu1>0.2</mu1>
    <mu2>0.2</mu2>
    <selfCollide>true</selfCollide>
  </gazebo>
  <gazebo reference="Nlink_board_4">
    <material>Gazebo/Silver</material>
    <mu1>0.2</mu1>
    <mu2>0.2</mu2>
    <selfCollide>true</selfCollide>
  </gazebo>
  <gazebo reference="Plink_board_3">
    <material>Gazebo/Silver</material>
    <mu1>0.2</mu1>
    <mu2>0.2</mu2>
    <selfCollide>true</selfCollide>
  </gazebo>
  <gazebo reference="Plink_board_4">
    <material>Gazebo/Silver</material>
    <mu1>0.2</mu1>
    <mu2>0.2</mu2>
    <selfCollide>true</selfCollide>
  </gazebo>
  <gazebo reference="Pcalf_1">
    <material>Gazebo/Silver</material>
    <mu1>0.2</mu1>
    <mu2>0.2</mu2>
    <selfCollide>true</selfCollide>
  </gazebo>
  <gazebo reference="Pcalf_2">
    <material>Gazebo/Silver</material>
    <mu1>0.2</mu1>
    <mu2>0.2</mu2>
    <selfCollide>true</selfCollide>
  </gazebo>
  <gazebo reference="Pcalf_3">
    <material>Gazebo/Silver</material>
    <mu1>0.2</mu1>
    <mu2>0.2</mu2>
    <selfCollide>true</selfCollide>
  </gazebo>
  <gazebo reference="Pcalf_4">
    <material>Gazebo/Silver</material>
    <mu1>0.2</mu1>
    <mu2>0.2</mu2>
    <selfCollide>true</selfCollide>
  </gazebo>
  <gazebo reference="Ncalf_1">
    <material>Gazebo/Silver</material>
    <mu1>0.2</mu1>
    <mu2>0.2</mu2>
    <selfCollide>true</selfCollide>
  </gazebo>
  <gazebo reference="Ncalf_4">
    <material>Gazebo/Silver</material>
    <mu1>0.2</mu1>
    <mu2>0.2</mu2>
    <selfCollide>true</selfCollide>
  </gazebo>
  <gazebo reference="Ncalf_5">
    <material>Gazebo/Silver</material>
    <mu1>0.2</mu1>
    <mu2>0.2</mu2>
    <selfCollide>true</selfCollide>
  </gazebo>
  <gazebo reference="Ncalf_6">
    <material>Gazebo/Silver</material>
    <mu1>0.2</mu1>
    <mu2>0.2</mu2>
    <selfCollide>true</selfCollide>
  </gazebo>
  <link name="base_link">
    <inertial>
      <origin xyz="-0.0051807055685298845 0.0016789525525093716 0.04999999522434671" rpy="0 0 0"/>
      <mass value="263.0006663023306"/>
      <inertia ixx="4.566198" iyy="12.702097" izz="16.830003" ixy="0.152261" iyz="-0.0" ixz="0.0"/>
    </inertial>
    <visual>
      <origin xyz="0 0 0" rpy="0 0 0"/>
      <geometry>
        <mesh filename="package://spider_description/meshes/base_link.stl" scale="0.001 0.001 0.001"/>
      </geometry>
      <material name="silver"/>
    </visual>
    <collision>
      <origin xyz="0 0 0" rpy="0 0 0"/>
      <geometry>
        <mesh filename="package://spider_description/meshes/base_link.stl" scale="0.001 0.001 0.001"/>
      </geometry>
    </collision>
  </link>
  <link name="Plink_board_1">
    <inertial>
      <origin xyz="0.019878880406234756 0.010141771791210993 0.0" rpy="0 0 0"/>
      <mass value="0.14930413438956674"/>
      <inertia ixx="4e-05" iyy="7.5e-05" izz="7.4e-05" ixy="-1.9e-05" iyz="0.0" ixz="0.0"/>
    </inertial>
    <visual>
      <origin xyz="-0.45001 -0.1 -0.05" rpy="0 0 0"/>
      <geometry>
        <mesh filename="package://spider_description/meshes/Plink_board_1.stl" scale="0.001 0.001 0.001"/>
      </geometry>
      <material name="silver"/>
    </visual>
    <collision>
      <origin xyz="-0.45001 -0.1 -0.05" rpy="0 0 0"/>
      <geometry>
        <mesh filename="package://spider_description/meshes/Plink_board_1.stl" scale="0.001 0.001 0.001"/>
      </geometry>
    </collision>
  </link>
  <link name="Plink_board_2">
    <inertial>
      <origin xyz="0.019878880406234756 0.010141771791210952 -4.85722573273506e-17" rpy="0 0 0"/>
      <mass value="0.14930413438956674"/>
      <inertia ixx="4e-05" iyy="7.5e-05" izz="7.4e-05" ixy="-1.9e-05" iyz="-0.0" ixz="-0.0"/>
    </inertial>
    <visual>
      <origin xyz="-0.25001 -0.25 -0.05" rpy="0 0 0"/>
      <geometry>
        <mesh filename="package://spider_description/meshes/Plink_board_2.stl" scale="0.001 0.001 0.001"/>
      </geometry>
      <material name="silver"/>
    </visual>
    <collision>
      <origin xyz="-0.25001 -0.25 -0.05" rpy="0 0 0"/>
      <geometry>
        <mesh filename="package://spider_description/meshes/Plink_board_2.stl" scale="0.001 0.001 0.001"/>
      </geometry>
    </collision>
  </link>
  <link name="Nlink_board_1">
    <inertial>
      <origin xyz="-0.019878880691994172 0.010141771942031585 -1.3877787807814457e-17" rpy="0 0 0"/>
      <mass value="0.14930413883458316"/>
      <inertia ixx="4e-05" iyy="7.5e-05" izz="7.4e-05" ixy="1.9e-05" iyz="-0.0" ixz="0.0"/>
    </inertial>
    <visual>
      <origin xyz="0.25001 -0.25 -0.05" rpy="0 0 0"/>
      <geometry>
        <mesh filename="package://spider_description/meshes/Nlink_board_1.stl" scale="0.001 0.001 0.001"/>
      </geometry>
      <material name="silver"/>
    </visual>
    <collision>
      <origin xyz="0.25001 -0.25 -0.05" rpy="0 0 0"/>
      <geometry>
        <mesh filename="package://spider_description/meshes/Nlink_board_1.stl" scale="0.001 0.001 0.001"/>
      </geometry>
    </collision>
  </link>
  <link name="Nlink_board_2">
    <inertial>
      <origin xyz="-0.01987888069199395 0.010141771942031613 1.3877787807814457e-17" rpy="0 0 0"/>
      <mass value="0.14930413883458316"/>
      <inertia ixx="4e-05" iyy="7.5e-05" izz="7.4e-05" ixy="1.9e-05" iyz="0.0" ixz="0.0"/>
    </inertial>
    <visual>
      <origin xyz="0.45001 -0.125 -0.05" rpy="0 0 0"/>
      <geometry>
        <mesh filename="package://spider_description/meshes/Nlink_board_2.stl" scale="0.001 0.001 0.001"/>
      </geometry>
      <material name="silver"/>
    </visual>
    <collision>
      <origin xyz="0.45001 -0.125 -0.05" rpy="0 0 0"/>
      <geometry>
        <mesh filename="package://spider_description/meshes/Nlink_board_2.stl" scale="0.001 0.001 0.001"/>
      </geometry>
    </collision>
  </link>
  <link name="Nlink_board_3">
    <inertial>
      <origin xyz="0.019878880691994005 -0.010141771942031613 0.0" rpy="0 0 0"/>
      <mass value="0.14930413883458316"/>
      <inertia ixx="4e-05" iyy="7.5e-05" izz="7.4e-05" ixy="1.9e-05" iyz="0.0" ixz="-0.0"/>
    </inertial>
    <visual>
      <origin xyz="-0.45001 0.1 -0.045" rpy="0 0 0"/>
      <geometry>
        <mesh filename="package://spider_description/meshes/Nlink_board_3.stl" scale="0.001 0.001 0.001"/>
      </geometry>
      <material name="silver"/>
    </visual>
    <collision>
      <origin xyz="-0.45001 0.1 -0.045" rpy="0 0 0"/>
      <geometry>
        <mesh filename="package://spider_description/meshes/Nlink_board_3.stl" scale="0.001 0.001 0.001"/>
      </geometry>
    </collision>
  </link>
  <link name="Nlink_board_4">
    <inertial>
      <origin xyz="0.019878880691994172 -0.01014177194203153 -1.3877787807814457e-17" rpy="0 0 0"/>
      <mass value="0.14930413883458316"/>
      <inertia ixx="4e-05" iyy="7.5e-05" izz="7.4e-05" ixy="1.9e-05" iyz="0.0" ixz="-0.0"/>
    </inertial>
    <visual>
      <origin xyz="-0.25001 0.25 -0.05" rpy="0 0 0"/>
      <geometry>
        <mesh filename="package://spider_description/meshes/Nlink_board_4.stl" scale="0.001 0.001 0.001"/>
      </geometry>
      <material name="silver"/>
    </visual>
    <collision>
      <origin xyz="-0.25001 0.25 -0.05" rpy="0 0 0"/>
      <geometry>
        <mesh filename="package://spider_description/meshes/Nlink_board_4.stl" scale="0.001 0.001 0.001"/>
      </geometry>
    </collision>
  </link>
  <link name="Plink_board_3">
    <inertial>
      <origin xyz="-0.019878880406234756 -0.010141771791210952 -4.85722573273506e-17" rpy="0 0 0"/>
      <mass value="0.14930413438956674"/>
      <inertia ixx="4e-05" iyy="7.5e-05" izz="7.4e-05" ixy="-1.9e-05" iyz="0.0" ixz="0.0"/>
    </inertial>
    <visual>
      <origin xyz="0.25001 0.25 -0.05" rpy="0 0 0"/>
      <geometry>
        <mesh filename="package://spider_description/meshes/Plink_board_3.stl" scale="0.001 0.001 0.001"/>
      </geometry>
      <material name="silver"/>
    </visual>
    <collision>
      <origin xyz="0.25001 0.25 -0.05" rpy="0 0 0"/>
      <geometry>
        <mesh filename="package://spider_description/meshes/Plink_board_3.stl" scale="0.001 0.001 0.001"/>
      </geometry>
    </collision>
  </link>
  <link name="Plink_board_4">
    <inertial>
      <origin xyz="-0.019878880406234534 -0.01014177179121098 -6.938893903907228e-18" rpy="0 0 0"/>
      <mass value="0.14930413438956674"/>
      <inertia ixx="4e-05" iyy="7.5e-05" izz="7.4e-05" ixy="-1.9e-05" iyz="0.0" ixz="0.0"/>
    </inertial>
    <visual>
      <origin xyz="0.45001 0.1 -0.045" rpy="0 0 0"/>
      <geometry>
        <mesh filename="package://spider_description/meshes/Plink_board_4.stl" scale="0.001 0.001 0.001"/>
      </geometry>
      <material name="silver"/>
    </visual>
    <collision>
      <origin xyz="0.45001 0.1 -0.045" rpy="0 0 0"/>
      <geometry>
        <mesh filename="package://spider_description/meshes/Plink_board_4.stl" scale="0.001 0.001 0.001"/>
      </geometry>
    </collision>
  </link>
  <link name="Pcalf_1">
    <inertial>
      <origin xyz="-5.55138551794343e-09 0.002499549328502923 -0.1307761990337935" rpy="0 0 0"/>
      <mass value="0.8567715125260319"/>
      <inertia ixx="0.003554" iyy="0.003641" izz="0.00064" ixy="0.0" iyz="0.0" ixz="-0.0"/>
    </inertial>
    <visual>
      <origin xyz="-0.48001 -0.12001 -0.05" rpy="0 0 0"/>
      <geometry>
        <mesh filename="package://spider_description/meshes/Pcalf_1.stl" scale="0.001 0.001 0.001"/>
      </geometry>
      <material name="silver"/>
    </visual>
    <collision>
      <origin xyz="-0.48001 -0.12001 -0.05" rpy="0 0 0"/>
      <geometry>
        <mesh filename="package://spider_description/meshes/Pcalf_1.stl" scale="0.001 0.001 0.001"/>
      </geometry>
    </collision>
  </link>
  <link name="Pcalf_2">
    <inertial>
      <origin xyz="-5.55138551794343e-09 0.0024995493285029924 -0.1307761990337935" rpy="0 0 0"/>
      <mass value="0.8567715125260319"/>
      <inertia ixx="0.003554" iyy="0.003641" izz="0.00064" ixy="0.0" iyz="0.0" ixz="-0.0"/>
    </inertial>
    <visual>
      <origin xyz="-0.28001 -0.27001 -0.05" rpy="0 0 0"/>
      <geometry>
        <mesh filename="package://spider_description/meshes/Pcalf_2.stl" scale="0.001 0.001 0.001"/>
      </geometry>
      <material name="silver"/>
    </visual>
    <collision>
      <origin xyz="-0.28001 -0.27001 -0.05" rpy="0 0 0"/>
      <geometry>
        <mesh filename="package://spider_description/meshes/Pcalf_2.stl" scale="0.001 0.001 0.001"/>
      </geometry>
    </collision>
  </link>
  <link name="Pcalf_3">
    <inertial>
      <origin xyz="3.83634596312632e-09 0.002499549626526154 -0.1307761990337935" rpy="0 0 0"/>
      <mass value="0.8567715125260319"/>
      <inertia ixx="0.003554" iyy="0.003641" izz="0.00064" ixy="0.0" iyz="0.0" ixz="-0.0"/>
    </inertial>
    <visual>
      <origin xyz="0.28001 -0.27001 -0.05" rpy="0 0 0"/>
      <geometry>
        <mesh filename="package://spider_description/meshes/Pcalf_3.stl" scale="0.001 0.001 0.001"/>
      </geometry>
      <material name="silver"/>
    </visual>
    <collision>
      <origin xyz="0.28001 -0.27001 -0.05" rpy="0 0 0"/>
      <geometry>
        <mesh filename="package://spider_description/meshes/Pcalf_3.stl" scale="0.001 0.001 0.001"/>
      </geometry>
    </collision>
  </link>
  <link name="Pcalf_4">
    <inertial>
      <origin xyz="3.836345241481354e-09 0.0024995496265261263 -0.1307761990337935" rpy="0 0 0"/>
      <mass value="0.8567715125260319"/>
      <inertia ixx="0.003554" iyy="0.003641" izz="0.00064" ixy="0.0" iyz="0.0" ixz="-0.0"/>
    </inertial>
    <visual>
      <origin xyz="0.48001 -0.14501 -0.05" rpy="0 0 0"/>
      <geometry>
        <mesh filename="package://spider_description/meshes/Pcalf_4.stl" scale="0.001 0.001 0.001"/>
      </geometry>
      <material name="silver"/>
    </visual>
    <collision>
      <origin xyz="0.48001 -0.14501 -0.05" rpy="0 0 0"/>
      <geometry>
        <mesh filename="package://spider_description/meshes/Pcalf_4.stl" scale="0.001 0.001 0.001"/>
      </geometry>
    </collision>
  </link>
  <link name="Ncalf_1">
    <inertial>
      <origin xyz="-3.836346018637471e-09 -0.0024995496265262374 -0.1307761990337935" rpy="0 0 0"/>
      <mass value="0.8567715125260319"/>
      <inertia ixx="0.003554" iyy="0.003641" izz="0.00064" ixy="0.0" iyz="-0.0" ixz="0.0"/>
    </inertial>
    <visual>
      <origin xyz="-0.48001 0.12001 -0.045" rpy="0 0 0"/>
      <geometry>
        <mesh filename="package://spider_description/meshes/Ncalf_1.stl" scale="0.001 0.001 0.001"/>
      </geometry>
      <material name="silver"/>
    </visual>
    <collision>
      <origin xyz="-0.48001 0.12001 -0.045" rpy="0 0 0"/>
      <geometry>
        <mesh filename="package://spider_description/meshes/Ncalf_1.stl" scale="0.001 0.001 0.001"/>
      </geometry>
    </collision>
  </link>
  <link name="Ncalf_4">
    <inertial>
      <origin xyz="-3.83634596312632e-09 -0.0024995496265262096 -0.1307761990337936" rpy="0 0 0"/>
      <mass value="0.8567715125260319"/>
      <inertia ixx="0.003554" iyy="0.003641" izz="0.00064" ixy="0.0" iyz="-0.0" ixz="0.0"/>
    </inertial>
    <visual>
      <origin xyz="-0.28001 0.27001 -0.05" rpy="0 0 0"/>
      <geometry>
        <mesh filename="package://spider_description/meshes/Ncalf_4.stl" scale="0.001 0.001 0.001"/>
      </geometry>
      <material name="silver"/>
    </visual>
    <collision>
      <origin xyz="-0.28001 0.27001 -0.05" rpy="0 0 0"/>
      <geometry>
        <mesh filename="package://spider_description/meshes/Ncalf_4.stl" scale="0.001 0.001 0.001"/>
      </geometry>
    </collision>
  </link>
  <link name="Ncalf_5">
    <inertial>
      <origin xyz="5.55138551794343e-09 -0.002499549328503048 -0.1307761990337935" rpy="0 0 0"/>
      <mass value="0.8567715125260319"/>
      <inertia ixx="0.003554" iyy="0.003641" izz="0.00064" ixy="0.0" iyz="-0.0" ixz="0.0"/>
    </inertial>
    <visual>
      <origin xyz="0.28001 0.27001 -0.05" rpy="0 0 0"/>
      <geometry>
        <mesh filename="package://spider_description/meshes/Ncalf_5.stl" scale="0.001 0.001 0.001"/>
      </geometry>
      <material name="silver"/>
    </visual>
    <collision>
      <origin xyz="0.28001 0.27001 -0.05" rpy="0 0 0"/>
      <geometry>
        <mesh filename="package://spider_description/meshes/Ncalf_5.stl" scale="0.001 0.001 0.001"/>
      </geometry>
    </collision>
  </link>
  <link name="Ncalf_6">
    <inertial>
      <origin xyz="5.551385628965733e-09 -0.002499549328503034 -0.1307761990337935" rpy="0 0 0"/>
      <mass value="0.8567715125260319"/>
      <inertia ixx="0.003554" iyy="0.003641" izz="0.00064" ixy="0.0" iyz="-0.0" ixz="0.0"/>
    </inertial>
    <visual>
      <origin xyz="0.48001 0.12001 -0.045" rpy="0 0 0"/>
      <geometry>
        <mesh filename="package://spider_description/meshes/Ncalf_6.stl" scale="0.001 0.001 0.001"/>
      </geometry>
      <material name="silver"/>
    </visual>
    <collision>
      <origin xyz="0.48001 0.12001 -0.045" rpy="0 0 0"/>
      <geometry>
        <mesh filename="package://spider_description/meshes/Ncalf_6.stl" scale="0.001 0.001 0.001"/>
      </geometry>
    </collision>
  </link>
  <joint name="Revolute 1" type="continuous">
    <origin xyz="0.45001 0.1 0.05" rpy="0 0 0"/>
    <parent link="base_link"/>
    <child link="Plink_board_1"/>
    <axis xyz="1.0 0.0 0.0"/>
  </joint>
  <joint name="Revolute 2" type="continuous">
    <origin xyz="0.25001 0.25 0.05" rpy="0 0 0"/>
    <parent link="base_link"/>
    <child link="Plink_board_2"/>
    <axis xyz="1.0 0.0 0.0"/>
  </joint>
  <joint name="Revolute 3" type="continuous">
    <origin xyz="-0.25001 0.25 0.05" rpy="0 0 0"/>
    <parent link="base_link"/>
    <child link="Nlink_board_1"/>
    <axis xyz="-1.0 0.0 0.0"/>
  </joint>
  <joint name="Revolute 4" type="continuous">
    <origin xyz="-0.45001 0.125 0.05" rpy="0 0 0"/>
    <parent link="base_link"/>
    <child link="Nlink_board_2"/>
    <axis xyz="-1.0 0.0 0.0"/>
  </joint>
  <joint name="Revolute 5" type="continuous">
    <origin xyz="0.45001 -0.1 0.045" rpy="0 0 0"/>
    <parent link="base_link"/>
    <child link="Nlink_board_3"/>
    <axis xyz="1.0 0.0 0.0"/>
  </joint>
  <joint name="Revolute 6" type="continuous">
    <origin xyz="0.25001 -0.25 0.05" rpy="0 0 0"/>
    <parent link="base_link"/>
    <child link="Nlink_board_4"/>
    <axis xyz="1.0 0.0 0.0"/>
  </joint>
  <joint name="Revolute 7" type="continuous">
    <origin xyz="-0.25001 -0.25 0.05" rpy="0 0 0"/>
    <parent link="base_link"/>
    <child link="Plink_board_3"/>
    <axis xyz="-1.0 0.0 0.0"/>
  </joint>
  <joint name="Revolute 8" type="continuous">
    <origin xyz="-0.45001 -0.1 0.045" rpy="0 0 0"/>
    <parent link="base_link"/>
    <child link="Plink_board_4"/>
    <axis xyz="-1.0 0.0 0.0"/>
  </joint>
  <joint name="Revolute 9" type="continuous">
    <origin xyz="0.03 0.02001 0.0" rpy="0 0 0"/>
    <parent link="Plink_board_1"/>
    <child link="Pcalf_1"/>
    <axis xyz="0.0 1.0 0.0"/>
  </joint>
  <joint name="Revolute 10" type="continuous">
    <origin xyz="0.03 0.02001 0.0" rpy="0 0 0"/>
    <parent link="Plink_board_2"/>
    <child link="Pcalf_2"/>
    <axis xyz="0.0 1.0 0.0"/>
  </joint>
  <joint name="Revolute 11" type="continuous">
    <origin xyz="-0.03 0.02001 0.0" rpy="0 0 0"/>
    <parent link="Nlink_board_1"/>
    <child link="Pcalf_3"/>
    <axis xyz="0.0 1.0 0.0"/>
  </joint>
  <joint name="Revolute 12" type="continuous">
    <origin xyz="-0.03 0.02001 0.0" rpy="0 0 0"/>
    <parent link="Nlink_board_2"/>
    <child link="Pcalf_4"/>
    <axis xyz="0.0 1.0 0.0"/>
  </joint>
  <joint name="Revolute 13" type="continuous">
    <origin xyz="0.03 -0.02001 0.0" rpy="0 0 0"/>
    <parent link="Nlink_board_3"/>
    <child link="Ncalf_1"/>
    <axis xyz="0.0 -1.0 0.0"/>
  </joint>
  <joint name="Revolute 14" type="continuous">
    <origin xyz="0.03 -0.02001 0.0" rpy="0 0 0"/>
    <parent link="Nlink_board_4"/>
    <child link="Ncalf_4"/>
    <axis xyz="0.0 -1.0 0.0"/>
  </joint>
  <joint name="Revolute 15" type="continuous">
    <origin xyz="-0.03 -0.02001 0.0" rpy="0 0 0"/>
    <parent link="Plink_board_3"/>
    <child link="Ncalf_5"/>
    <axis xyz="0.0 -1.0 0.0"/>
  </joint>
  <joint name="Revolute 16" type="continuous">
    <origin xyz="-0.03 -0.02001 0.0" rpy="0 0 0"/>
    <parent link="Plink_board_4"/>
    <child link="Ncalf_6"/>
    <axis xyz="0.0 -1.0 0.0"/>
  </joint>
</robot>
